Workbook

Sheet Red
A1: GENERADOR DE MODELOS DE REDES SINTÉTICAS DE FINANCIACIÓN DEL TERRORISMO | S1: Marina Sarti Pineda - marzo 2026
A3: TIPOS DE NODO | E3: NODOS | J3: ENLACES ENTRE NODOS
A4: Tipo | B4: Descripción | C4: Capa | E4: NodoID | F4: Nombre | G4: Tipo | H4: Activo | J4: EdgeID | K4: Nodo Origen | L4: Nodo Destino | M4: Tipo de Enlace | N4: Activo | O4: Tipo de Justificación | P4: Coste | Q4: Eficiencia | R4: Exposición | S4: Capacidad | T4: Resiliencia | U4: Fuente GAFI | V4: Observaciones | W4: Peso | X4: Coste (peso) | Y4: Eficiencia (peso) | Z4: Exposición (peso) | AA4: Capacidad (peso) | AB4: Resiliencia (peso) | AC4: ValorOperativo (peso)
A5: O | B5: Origen | C5: 1 | E5: O1 | F5: Coerción y cobros forzosos | G5: O | H5: 1 | J5: E051 | K5: G1 | L5: D | M5: principal | N5: 1 | O5: T | P5: Bajo | Q5: Alto | R5: Medio | S5: Alto | T5: Medio | U5: GAFI - FT risks | V5: Tesorería central → destino | W5: =IFERROR(_xlfn.XLOOKUP(tblEnlaces[[#This Row],[Eficiencia]],tblPesosCoste[Valor],#REF!),0)+IFERROR(_xlfn.XLOOKUP(tblEnlaces[[#This Row],[Capacidad]],tblPesosCoste[Valor],#REF!),0)+IFERROR(_xlfn.XLOOKUP(tblEnlaces[[#This Row],[Resiliencia]],tblPesosCoste[Valor],#REF!),0)+IFERROR(_xlfn.XLOOKUP(tblEnlaces[[#This Row],[Coste]],tblPesosCoste[Valor],tblPesosCoste[Coste]),0)+IFERROR(_xlfn.XLOOKUP(tblEnlaces[[#This Row],[Exposición]],tblPesosCoste[Valor],#REF!),0) -> 5 | X5: =IFERROR(_xlfn.XLOOKUP(tblEnlaces[[#This Row],[Coste]],tblPesosCoste[Valor],tblPesosCoste[Coste],0),0) -> 5 | Y5: =IFERROR(_xlfn.XLOOKUP(tblEnlaces[[#This Row],[Eficiencia]],tblPesosValorOperativo[Valor],tblPesosValorOperativo[Eficiencia],0),0) -> 5 | Z5: =IFERROR(_xlfn.XLOOKUP(tblEnlaces[[#This Row],[Exposición]],tblPesosValorOperativo[Valor],tblPesosValorOperativo[Exposición],0),0) -> 3 | AA5: =IFERROR(_xlfn.XLOOKUP(tblEnlaces[[#This Row],[Capacidad]],tblPesosValorOperativo[Valor],tblPesosValorOperativo[Capacidad],0),0) -> 5 | AB5: =IFERROR(_xlfn.XLOOKUP(tblEnlaces[[#This Row],[Resiliencia]],tblPesosValorOperativo[Valor],tblPesosValorOperativo[Resiliencia],0),0) -> 3 | AC5: =tblEnlaces[[#This Row],[Eficiencia (peso)]]+tblEnlaces[[#This Row],[Exposición (peso)]]+tblEnlaces[[#This Row],[Capacidad (peso)]]+tblEnlaces[[#This Row],[Resiliencia (peso)]] -> 16
A6: I | B6: Intermediario | C6: 2 | E6: O2 | F6: Contrabando / tráfico / comercio ilícito | G6: O | H6: 1 | J6: E012 | K6: O4 | L6: I4 | M6: principal | N6: 1 | O6: T | P6: Bajo | Q6: Alto | R6: Medio | S6: Medio | T6: Medio | U6: GAFI - FT risks | V6: Microfinanciación y dinero móvil | W6: =IFERROR(_xlfn.XLOOKUP(tblEnlaces[[#This Row],[Eficiencia]],tblPesosCoste[Valor],#REF!),0)+IFERROR(_xlfn.XLOOKUP(tblEnlaces[[#This Row],[Capacidad]],tblPesosCoste[Valor],#REF!),0)+IFERROR(_xlfn.XLOOKUP(tblEnlaces[[#This Row],[Resiliencia]],tblPesosCoste[Valor],#REF!),0)+IFERROR(_xlfn.XLOOKUP(tblEnlaces[[#This Row],[Coste]],tblPesosCoste[Valor],tblPesosCoste[Coste]),0)+IFERROR(_xlfn.XLOOKUP(tblEnlaces[[#This Row],[Exposición]],tblPesosCoste[Valor],#REF!),0) -> 5 | X6: =IFERROR(_xlfn.XLOOKUP(tblEnlaces[[#This Row],[Coste]],tblPesosCoste[Valor],tblPesosCoste[Coste],0),0) -> 5 | Y6: =IFERROR(_xlfn.XLOOKUP(tblEnlaces[[#This Row],[Eficiencia]],tblPesosValorOperativo[Valor],tblPesosValorOperativo[Eficiencia],0),0) -> 5 | Z6: =IFERROR(_xlfn.XLOOKUP(tblEnlaces[[#This Row],[Exposición]],tblPesosValorOperativo[Valor],tblPesosValorOperativo[Exposición],0),0) -> 3 | AA6: =IFERROR(_xlfn.XLOOKUP(tblEnlaces[[#This Row],[Capacidad]],tblPesosValorOperativo[Valor],tblPesosValorOperativo[Capacidad],0),0) -> 3 | AB6: =IFERROR(_xlfn.XLOOKUP(tblEnlaces[[#This Row],[Resiliencia]],tblPesosValorOperativo[Valor],tblPesosValorOperativo[Resiliencia],0),0) -> 3 | AC6: =tblEnlaces[[#This Row],[Eficiencia (peso)]]+tblEnlaces[[#This Row],[Exposición (peso)]]+tblEnlaces[[#This Row],[Capacidad (peso)]]+tblEnlaces[[#This Row],[Resiliencia (peso)]] -> 14
A7: G | B7: Gestión | C7: 3 | E7: O3 | F7: Explotación de recursos naturales | G7: O | H7: 1 | J7: E046 | K7: G2 | L7: D | M7: principal | N7: 1 | O7: T | P7: Bajo | Q7: Alto | R7: Medio | S7: Medio | T7: Medio | U7: GAFI - FT risks | V7: Células/centros regionales → destino | W7: =IFERROR(_xlfn.XLOOKUP(tblEnlaces[[#This Row],[Eficiencia]],tblPesosCoste[Valor],#REF!),0)+IFERROR(_xlfn.XLOOKUP(tblEnlaces[[#This Row],[Capacidad]],tblPesosCoste[Valor],#REF!),0)+IFERROR(_xlfn.XLOOKUP(tblEnlaces[[#This Row],[Resiliencia]],tblPesosCoste[Valor],#REF!),0)+IFERROR(_xlfn.XLOOKUP(tblEnlaces[[#This Row],[Coste]],tblPesosCoste[Valor],tblPesosCoste[Coste]),0)+IFERROR(_xlfn.XLOOKUP(tblEnlaces[[#This Row],[Exposición]],tblPesosCoste[Valor],#REF!),0) -> 5 | X7: =IFERROR(_xlfn.XLOOKUP(tblEnlaces[[#This Row],[Coste]],tblPesosCoste[Valor],tblPesosCoste[Coste],0),0) -> 5 | Y7: =IFERROR(_xlfn.XLOOKUP(tblEnlaces[[#This Row],[Eficiencia]],tblPesosValorOperativo[Valor],tblPesosValorOperativo[Eficiencia],0),0) -> 5 | Z7: =IFERROR(_xlfn.XLOOKUP(tblEnlaces[[#This Row],[Exposición]],tblPesosValorOperativo[Valor],tblPesosValorOperativo[Exposición],0),0) -> 3 | AA7: =IFERROR(_xlfn.XLOOKUP(tblEnlaces[[#This Row],[Capacidad]],tblPesosValorOperativo[Valor],tblPesosValorOperativo[Capacidad],0),0) -> 3 | AB7: =IFERROR(_xlfn.XLOOKUP(tblEnlaces[[#This Row],[Resiliencia]],tblPesosValorOperativo[Valor],tblPesosValorOperativo[Resiliencia],0),0) -> 3 | AC7: =tblEnlaces[[#This Row],[Eficiencia (peso)]]+tblEnlaces[[#This Row],[Exposición (peso)]]+tblEnlaces[[#This Row],[Capacidad (peso)]]+tblEnlaces[[#This Row],[Resiliencia (peso)]] -> 14
A8: D | B8: Destino | C8: 4 | E8: O4 | F8: Autofinanciación lícita / microfinanciación | G8: O | H8: 1 | J8: E050 | K8: G3 | L8: D | M8: principal | N8: 1 | O8: T | P8: Bajo | Q8: Alto | R8: Medio | S8: Medio | T8: Medio | U8: GAFI - FT risks | V8: Facilitador → destino | W8: =IFERROR(_xlfn.XLOOKUP(tblEnlaces[[#This Row],[Eficiencia]],tblPesosCoste[Valor],#REF!),0)+IFERROR(_xlfn.XLOOKUP(tblEnlaces[[#This Row],[Capacidad]],tblPesosCoste[Valor],#REF!),0)+IFERROR(_xlfn.XLOOKUP(tblEnlaces[[#This Row],[Resiliencia]],tblPesosCoste[Valor],#REF!),0)+IFERROR(_xlfn.XLOOKUP(tblEnlaces[[#This Row],[Coste]],tblPesosCoste[Valor],tblPesosCoste[Coste]),0)+IFERROR(_xlfn.XLOOKUP(tblEnlaces[[#This Row],[Exposición]],tblPesosCoste[Valor],#REF!),0) -> 5 | X8: =IFERROR(_xlfn.XLOOKUP(tblEnlaces[[#This Row],[Coste]],tblPesosCoste[Valor],tblPesosCoste[Coste],0),0) -> 5 | Y8: =IFERROR(_xlfn.XLOOKUP(tblEnlaces[[#This Row],[Eficiencia]],tblPesosValorOperativo[Valor],tblPesosValorOperativo[Eficiencia],0),0) -> 5 | Z8: =IFERROR(_xlfn.XLOOKUP(tblEnlaces[[#This Row],[Exposición]],tblPesosValorOperativo[Valor],tblPesosValorOperativo[Exposición],0),0) -> 3 | AA8: =IFERROR(_xlfn.XLOOKUP(tblEnlaces[[#This Row],[Capacidad]],tblPesosValorOperativo[Valor],tblPesosValorOperativo[Capacidad],0),0) -> 3 | AB8: =IFERROR(_xlfn.XLOOKUP(tblEnlaces[[#This Row],[Resiliencia]],tblPesosValorOperativo[Valor],tblPesosValorOperativo[Resiliencia],0),0) -> 3 | AC8: =tblEnlaces[[#This Row],[Eficiencia (peso)]]+tblEnlaces[[#This Row],[Exposición (peso)]]+tblEnlaces[[#This Row],[Capacidad (peso)]]+tblEnlaces[[#This Row],[Resiliencia (peso)]] -> 14
E9: O5 | F9: Actividades económicas formales / negocios | G9: O | H9: 1 | J9: E041 | K9: G1 | L9: I6 | M9: principal | N9: 1 | O9: T | P9: Bajo-Medio | Q9: Alto | R9: Alto | S9: Alto | T9: Medio | U9: GAFI - FT risks | V9: Gestión central + banca | W9: =IFERROR(_xlfn.XLOOKUP(tblEnlaces[[#This Row],[Eficiencia]],tblPesosCoste[Valor],#REF!),0)+IFERROR(_xlfn.XLOOKUP(tblEnlaces[[#This Row],[Capacidad]],tblPesosCoste[Valor],#REF!),0)+IFERROR(_xlfn.XLOOKUP(tblEnlaces[[#This Row],[Resiliencia]],tblPesosCoste[Valor],#REF!),0)+IFERROR(_xlfn.XLOOKUP(tblEnlaces[[#This Row],[Coste]],tblPesosCoste[Valor],tblPesosCoste[Coste]),0)+IFERROR(_xlfn.XLOOKUP(tblEnlaces[[#This Row],[Exposición]],tblPesosCoste[Valor],#REF!),0) -> 4 | X9: =IFERROR(_xlfn.XLOOKUP(tblEnlaces[[#This Row],[Coste]],tblPesosCoste[Valor],tblPesosCoste[Coste],0),0) -> 4 | Y9: =IFERROR(_xlfn.XLOOKUP(tblEnlaces[[#This Row],[Eficiencia]],tblPesosValorOperativo[Valor],tblPesosValorOperativo[Eficiencia],0),0) -> 5 | Z9: =IFERROR(_xlfn.XLOOKUP(tblEnlaces[[#This Row],[Exposición]],tblPesosValorOperativo[Valor],tblPesosValorOperativo[Exposición],0),0) -> 1 | AA9: =IFERROR(_xlfn.XLOOKUP(tblEnlaces[[#This Row],[Capacidad]],tblPesosValorOperativo[Valor],tblPesosValorOperativo[Capacidad],0),0) -> 5 | AB9: =IFERROR(_xlfn.XLOOKUP(tblEnlaces[[#This Row],[Resiliencia]],tblPesosValorOperativo[Valor],tblPesosValorOperativo[Resiliencia],0),0) -> 3 | AC9: =tblEnlaces[[#This Row],[Eficiencia (peso)]]+tblEnlaces[[#This Row],[Exposición (peso)]]+tblEnlaces[[#This Row],[Capacidad (peso)]]+tblEnlaces[[#This Row],[Resiliencia (peso)]] -> 14
E10: O6 | F10: Donaciones / crowdfunding / apoyo online | G10: O | H10: 1 | J10: E004 | K10: O1 | L10: I4 | M10: secundario | N10: 1 | O10: T | P10: Bajo-Medio | Q10: Alto | R10: Medio | S10: Medio | T10: Medio | U10: GAFI - FT risks | V10: Cobros con dinero móvil | W10: =IFERROR(_xlfn.XLOOKUP(tblEnlaces[[#This Row],[Eficiencia]],tblPesosCoste[Valor],#REF!),0)+IFERROR(_xlfn.XLOOKUP(tblEnlaces[[#This Row],[Capacidad]],tblPesosCoste[Valor],#REF!),0)+IFERROR(_xlfn.XLOOKUP(tblEnlaces[[#This Row],[Resiliencia]],tblPesosCoste[Valor],#REF!),0)+IFERROR(_xlfn.XLOOKUP(tblEnlaces[[#This Row],[Coste]],tblPesosCoste[Valor],tblPesosCoste[Coste]),0)+IFERROR(_xlfn.XLOOKUP(tblEnlaces[[#This Row],[Exposición]],tblPesosCoste[Valor],#REF!),0) -> 4 | X10: =IFERROR(_xlfn.XLOOKUP(tblEnlaces[[#This Row],[Coste]],tblPesosCoste[Valor],tblPesosCoste[Coste],0),0) -> 4 | Y10: =IFERROR(_xlfn.XLOOKUP(tblEnlaces[[#This Row],[Eficiencia]],tblPesosValorOperativo[Valor],tblPesosValorOperativo[Eficiencia],0),0) -> 5 | Z10: =IFERROR(_xlfn.XLOOKUP(tblEnlaces[[#This Row],[Exposición]],tblPesosValorOperativo[Valor],tblPesosValorOperativo[Exposición],0),0) -> 3 | AA10: =IFERROR(_xlfn.XLOOKUP(tblEnlaces[[#This Row],[Capacidad]],tblPesosValorOperativo[Valor],tblPesosValorOperativo[Capacidad],0),0) -> 3 | AB10: =IFERROR(_xlfn.XLOOKUP(tblEnlaces[[#This Row],[Resiliencia]],tblPesosValorOperativo[Valor],tblPesosValorOperativo[Resiliencia],0),0) -> 3 | AC10: =tblEnlaces[[#This Row],[Eficiencia (peso)]]+tblEnlaces[[#This Row],[Exposición (peso)]]+tblEnlaces[[#This Row],[Capacidad (peso)]]+tblEnlaces[[#This Row],[Resiliencia (peso)]] -> 14
E11: I1 | F11: Efectivo | G11: I | H11: 1 | J11: E030 | K11: I4 | L11: G2 | M11: principal | N11: 1 | O11: T | P11: Bajo-Medio | Q11: Alto | R11: Medio | S11: Medio | T11: Medio | U11: GAFI - FT risks | V11: Dinero móvil y células | W11: =IFERROR(_xlfn.XLOOKUP(tblEnlaces[[#This Row],[Eficiencia]],tblPesosCoste[Valor],#REF!),0)+IFERROR(_xlfn.XLOOKUP(tblEnlaces[[#This Row],[Capacidad]],tblPesosCoste[Valor],#REF!),0)+IFERROR(_xlfn.XLOOKUP(tblEnlaces[[#This Row],[Resiliencia]],tblPesosCoste[Valor],#REF!),0)+IFERROR(_xlfn.XLOOKUP(tblEnlaces[[#This Row],[Coste]],tblPesosCoste[Valor],tblPesosCoste[Coste]),0)+IFERROR(_xlfn.XLOOKUP(tblEnlaces[[#This Row],[Exposición]],tblPesosCoste[Valor],#REF!),0) -> 4 | X11: =IFERROR(_xlfn.XLOOKUP(tblEnlaces[[#This Row],[Coste]],tblPesosCoste[Valor],tblPesosCoste[Coste],0),0) -> 4 | Y11: =IFERROR(_xlfn.XLOOKUP(tblEnlaces[[#This Row],[Eficiencia]],tblPesosValorOperativo[Valor],tblPesosValorOperativo[Eficiencia],0),0) -> 5 | Z11: =IFERROR(_xlfn.XLOOKUP(tblEnlaces[[#This Row],[Exposición]],tblPesosValorOperativo[Valor],tblPesosValorOperativo[Exposición],0),0) -> 3 | AA11: =IFERROR(_xlfn.XLOOKUP(tblEnlaces[[#This Row],[Capacidad]],tblPesosValorOperativo[Valor],tblPesosValorOperativo[Capacidad],0),0) -> 3 | AB11: =IFERROR(_xlfn.XLOOKUP(tblEnlaces[[#This Row],[Resiliencia]],tblPesosValorOperativo[Valor],tblPesosValorOperativo[Resiliencia],0),0) -> 3 | AC11: =tblEnlaces[[#This Row],[Eficiencia (peso)]]+tblEnlaces[[#This Row],[Exposición (peso)]]+tblEnlaces[[#This Row],[Capacidad (peso)]]+tblEnlaces[[#This Row],[Resiliencia (peso)]] -> 14
E12: I2 | F12: Hawala / HOSSP | G12: I | H12: 1 | J12: E045 | K12: G2 | L12: I4 | M12: principal | N12: 1 | O12: T | P12: Bajo-Medio | Q12: Alto | R12: Medio | S12: Medio | T12: Medio | U12: GAFI - FT risks | V12: Centros regionales y dinero móvil | W12: =IFERROR(_xlfn.XLOOKUP(tblEnlaces[[#This Row],[Eficiencia]],tblPesosCoste[Valor],#REF!),0)+IFERROR(_xlfn.XLOOKUP(tblEnlaces[[#This Row],[Capacidad]],tblPesosCoste[Valor],#REF!),0)+IFERROR(_xlfn.XLOOKUP(tblEnlaces[[#This Row],[Resiliencia]],tblPesosCoste[Valor],#REF!),0)+IFERROR(_xlfn.XLOOKUP(tblEnlaces[[#This Row],[Coste]],tblPesosCoste[Valor],tblPesosCoste[Coste]),0)+IFERROR(_xlfn.XLOOKUP(tblEnlaces[[#This Row],[Exposición]],tblPesosCoste[Valor],#REF!),0) -> 4 | X12: =IFERROR(_xlfn.XLOOKUP(tblEnlaces[[#This Row],[Coste]],tblPesosCoste[Valor],tblPesosCoste[Coste],0),0) -> 4 | Y12: =IFERROR(_xlfn.XLOOKUP(tblEnlaces[[#This Row],[Eficiencia]],tblPesosValorOperativo[Valor],tblPesosValorOperativo[Eficiencia],0),0) -> 5 | Z12: =IFERROR(_xlfn.XLOOKUP(tblEnlaces[[#This Row],[Exposición]],tblPesosValorOperativo[Valor],tblPesosValorOperativo[Exposición],0),0) -> 3 | AA12: =IFERROR(_xlfn.XLOOKUP(tblEnlaces[[#This Row],[Capacidad]],tblPesosValorOperativo[Valor],tblPesosValorOperativo[Capacidad],0),0) -> 3 | AB12: =IFERROR(_xlfn.XLOOKUP(tblEnlaces[[#This Row],[Resiliencia]],tblPesosValorOperativo[Valor],tblPesosValorOperativo[Resiliencia],0),0) -> 3 | AC12: =tblEnlaces[[#This Row],[Eficiencia (peso)]]+tblEnlaces[[#This Row],[Exposición (peso)]]+tblEnlaces[[#This Row],[Capacidad (peso)]]+tblEnlaces[[#This Row],[Resiliencia (peso)]] -> 14
E13: I3 | F13: MVTS / remesas | G13: I | H13: 1 | J13: E013 | K13: O4 | L13: I5 | M13: principal | N13: 1 | O13: T | P13: Bajo-Medio | Q13: Alto | R13: Medio-Alto | S13: Medio | T13: Medio | U13: GAFI - FT risks | V13: Microfinanciación y pagos online | W13: =IFERROR(_xlfn.XLOOKUP(tblEnlaces[[#This Row],[Eficiencia]],tblPesosCoste[Valor],#REF!),0)+IFERROR(_xlfn.XLOOKUP(tblEnlaces[[#This Row],[Capacidad]],tblPesosCoste[Valor],#REF!),0)+IFERROR(_xlfn.XLOOKUP(tblEnlaces[[#This Row],[Resiliencia]],tblPesosCoste[Valor],#REF!),0)+IFERROR(_xlfn.XLOOKUP(tblEnlaces[[#This Row],[Coste]],tblPesosCoste[Valor],tblPesosCoste[Coste]),0)+IFERROR(_xlfn.XLOOKUP(tblEnlaces[[#This Row],[Exposición]],tblPesosCoste[Valor],#REF!),0) -> 4 | X13: =IFERROR(_xlfn.XLOOKUP(tblEnlaces[[#This Row],[Coste]],tblPesosCoste[Valor],tblPesosCoste[Coste],0),0) -> 4 | Y13: =IFERROR(_xlfn.XLOOKUP(tblEnlaces[[#This Row],[Eficiencia]],tblPesosValorOperativo[Valor],tblPesosValorOperativo[Eficiencia],0),0) -> 5 | Z13: =IFERROR(_xlfn.XLOOKUP(tblEnlaces[[#This Row],[Exposición]],tblPesosValorOperativo[Valor],tblPesosValorOperativo[Exposición],0),0) -> 2 | AA13: =IFERROR(_xlfn.XLOOKUP(tblEnlaces[[#This Row],[Capacidad]],tblPesosValorOperativo[Valor],tblPesosValorOperativo[Capacidad],0),0) -> 3 | AB13: =IFERROR(_xlfn.XLOOKUP(tblEnlaces[[#This Row],[Resiliencia]],tblPesosValorOperativo[Valor],tblPesosValorOperativo[Resiliencia],0),0) -> 3 | AC13: =tblEnlaces[[#This Row],[Eficiencia (peso)]]+tblEnlaces[[#This Row],[Exposición (peso)]]+tblEnlaces[[#This Row],[Capacidad (peso)]]+tblEnlaces[[#This Row],[Resiliencia (peso)]] -> 13
E14: I4 | F14: Dinero móvil | G14: I | H14: 1 | J14: E017 | K14: O5 | L14: I5 | M14: secundario | N14: 1 | O14: T | P14: Bajo-Medio | Q14: Alto | R14: Medio-Alto | S14: Medio | T14: Medio | U14: GAFI - FT risks | V14: Pagos online en actividad comercial | W14: =IFERROR(_xlfn.XLOOKUP(tblEnlaces[[#This Row],[Eficiencia]],tblPesosCoste[Valor],#REF!),0)+IFERROR(_xlfn.XLOOKUP(tblEnlaces[[#This Row],[Capacidad]],tblPesosCoste[Valor],#REF!),0)+IFERROR(_xlfn.XLOOKUP(tblEnlaces[[#This Row],[Resiliencia]],tblPesosCoste[Valor],#REF!),0)+IFERROR(_xlfn.XLOOKUP(tblEnlaces[[#This Row],[Coste]],tblPesosCoste[Valor],tblPesosCoste[Coste]),0)+IFERROR(_xlfn.XLOOKUP(tblEnlaces[[#This Row],[Exposición]],tblPesosCoste[Valor],#REF!),0) -> 4 | X14: =IFERROR(_xlfn.XLOOKUP(tblEnlaces[[#This Row],[Coste]],tblPesosCoste[Valor],tblPesosCoste[Coste],0),0) -> 4 | Y14: =IFERROR(_xlfn.XLOOKUP(tblEnlaces[[#This Row],[Eficiencia]],tblPesosValorOperativo[Valor],tblPesosValorOperativo[Eficiencia],0),0) -> 5 | Z14: =IFERROR(_xlfn.XLOOKUP(tblEnlaces[[#This Row],[Exposición]],tblPesosValorOperativo[Valor],tblPesosValorOperativo[Exposición],0),0) -> 2 | AA14: =IFERROR(_xlfn.XLOOKUP(tblEnlaces[[#This Row],[Capacidad]],tblPesosValorOperativo[Valor],tblPesosValorOperativo[Capacidad],0),0) -> 3 | AB14: =IFERROR(_xlfn.XLOOKUP(tblEnlaces[[#This Row],[Resiliencia]],tblPesosValorOperativo[Valor],tblPesosValorOperativo[Resiliencia],0),0) -> 3 | AC14: =tblEnlaces[[#This Row],[Eficiencia (peso)]]+tblEnlaces[[#This Row],[Exposición (peso)]]+tblEnlaces[[#This Row],[Capacidad (peso)]]+tblEnlaces[[#This Row],[Resiliencia (peso)]] -> 13
E15: I5 | F15: Pagos online | G15: I | H15: 1 | J15: E020 | K15: O6 | L15: I5 | M15: principal | N15: 1 | O15: T | P15: Bajo-Medio | Q15: Alto | R15: Medio-Alto | S15: Medio | T15: Medio | U15: GAFI - FT risks | V15: Pagos integrados online | W15: =IFERROR(_xlfn.XLOOKUP(tblEnlaces[[#This Row],[Eficiencia]],tblPesosCoste[Valor],#REF!),0)+IFERROR(_xlfn.XLOOKUP(tblEnlaces[[#This Row],[Capacidad]],tblPesosCoste[Valor],#REF!),0)+IFERROR(_xlfn.XLOOKUP(tblEnlaces[[#This Row],[Resiliencia]],tblPesosCoste[Valor],#REF!),0)+IFERROR(_xlfn.XLOOKUP(tblEnlaces[[#This Row],[Coste]],tblPesosCoste[Valor],tblPesosCoste[Coste]),0)+IFERROR(_xlfn.XLOOKUP(tblEnlaces[[#This Row],[Exposición]],tblPesosCoste[Valor],#REF!),0) -> 4 | X15: =IFERROR(_xlfn.XLOOKUP(tblEnlaces[[#This Row],[Coste]],tblPesosCoste[Valor],tblPesosCoste[Coste],0),0) -> 4 | Y15: =IFERROR(_xlfn.XLOOKUP(tblEnlaces[[#This Row],[Eficiencia]],tblPesosValorOperativo[Valor],tblPesosValorOperativo[Eficiencia],0),0) -> 5 | Z15: =IFERROR(_xlfn.XLOOKUP(tblEnlaces[[#This Row],[Exposición]],tblPesosValorOperativo[Valor],tblPesosValorOperativo[Exposición],0),0) -> 2 | AA15: =IFERROR(_xlfn.XLOOKUP(tblEnlaces[[#This Row],[Capacidad]],tblPesosValorOperativo[Valor],tblPesosValorOperativo[Capacidad],0),0) -> 3 | AB15: =IFERROR(_xlfn.XLOOKUP(tblEnlaces[[#This Row],[Resiliencia]],tblPesosValorOperativo[Valor],tblPesosValorOperativo[Resiliencia],0),0) -> 3 | AC15: =tblEnlaces[[#This Row],[Eficiencia (peso)]]+tblEnlaces[[#This Row],[Exposición (peso)]]+tblEnlaces[[#This Row],[Capacidad (peso)]]+tblEnlaces[[#This Row],[Resiliencia (peso)]] -> 13
E16: I6 | F16: Servicios bancarios | G16: I | H16: 1 | J16: E031 | K16: I5 | L16: G2 | M16: principal | N16: 1 | O16: T | P16: Bajo-Medio | Q16: Alto | R16: Medio-Alto | S16: Medio | T16: Medio | U16: GAFI - FT risks | V16: Pagos online y estructuras descentralizadas | W16: =IFERROR(_xlfn.XLOOKUP(tblEnlaces[[#This Row],[Eficiencia]],tblPesosCoste[Valor],#REF!),0)+IFERROR(_xlfn.XLOOKUP(tblEnlaces[[#This Row],[Capacidad]],tblPesosCoste[Valor],#REF!),0)+IFERROR(_xlfn.XLOOKUP(tblEnlaces[[#This Row],[Resiliencia]],tblPesosCoste[Valor],#REF!),0)+IFERROR(_xlfn.XLOOKUP(tblEnlaces[[#This Row],[Coste]],tblPesosCoste[Valor],tblPesosCoste[Coste]),0)+IFERROR(_xlfn.XLOOKUP(tblEnlaces[[#This Row],[Exposición]],tblPesosCoste[Valor],#REF!),0) -> 4 | X16: =IFERROR(_xlfn.XLOOKUP(tblEnlaces[[#This Row],[Coste]],tblPesosCoste[Valor],tblPesosCoste[Coste],0),0) -> 4 | Y16: =IFERROR(_xlfn.XLOOKUP(tblEnlaces[[#This Row],[Eficiencia]],tblPesosValorOperativo[Valor],tblPesosValorOperativo[Eficiencia],0),0) -> 5 | Z16: =IFERROR(_xlfn.XLOOKUP(tblEnlaces[[#This Row],[Exposición]],tblPesosValorOperativo[Valor],tblPesosValorOperativo[Exposición],0),0) -> 2 | AA16: =IFERROR(_xlfn.XLOOKUP(tblEnlaces[[#This Row],[Capacidad]],tblPesosValorOperativo[Valor],tblPesosValorOperativo[Capacidad],0),0) -> 3 | AB16: =IFERROR(_xlfn.XLOOKUP(tblEnlaces[[#This Row],[Resiliencia]],tblPesosValorOperativo[Valor],tblPesosValorOperativo[Resiliencia],0),0) -> 3 | AC16: =tblEnlaces[[#This Row],[Eficiencia (peso)]]+tblEnlaces[[#This Row],[Exposición (peso)]]+tblEnlaces[[#This Row],[Capacidad (peso)]]+tblEnlaces[[#This Row],[Resiliencia (peso)]] -> 13
E17: I7 | F17: Tarjetas prepago / e-wallets | G17: I | H17: 1 | J17: E018 | K17: O5 | L17: I6 | M17: principal | N17: 1 | O17: T | P17: Medio | Q17: Alto | R17: Alto | S17: Alto | T17: Medio | U17: GAFI - FT risks | V17: Banca y transferencias | W17: =IFERROR(_xlfn.XLOOKUP(tblEnlaces[[#This Row],[Eficiencia]],tblPesosCoste[Valor],#REF!),0)+IFERROR(_xlfn.XLOOKUP(tblEnlaces[[#This Row],[Capacidad]],tblPesosCoste[Valor],#REF!),0)+IFERROR(_xlfn.XLOOKUP(tblEnlaces[[#This Row],[Resiliencia]],tblPesosCoste[Valor],#REF!),0)+IFERROR(_xlfn.XLOOKUP(tblEnlaces[[#This Row],[Coste]],tblPesosCoste[Valor],tblPesosCoste[Coste]),0)+IFERROR(_xlfn.XLOOKUP(tblEnlaces[[#This Row],[Exposición]],tblPesosCoste[Valor],#REF!),0) -> 3 | X17: =IFERROR(_xlfn.XLOOKUP(tblEnlaces[[#This Row],[Coste]],tblPesosCoste[Valor],tblPesosCoste[Coste],0),0) -> 3 | Y17: =IFERROR(_xlfn.XLOOKUP(tblEnlaces[[#This Row],[Eficiencia]],tblPesosValorOperativo[Valor],tblPesosValorOperativo[Eficiencia],0),0) -> 5 | Z17: =IFERROR(_xlfn.XLOOKUP(tblEnlaces[[#This Row],[Exposición]],tblPesosValorOperativo[Valor],tblPesosValorOperativo[Exposición],0),0) -> 1 | AA17: =IFERROR(_xlfn.XLOOKUP(tblEnlaces[[#This Row],[Capacidad]],tblPesosValorOperativo[Valor],tblPesosValorOperativo[Capacidad],0),0) -> 5 | AB17: =IFERROR(_xlfn.XLOOKUP(tblEnlaces[[#This Row],[Resiliencia]],tblPesosValorOperativo[Valor],tblPesosValorOperativo[Resiliencia],0),0) -> 3 | AC17: =tblEnlaces[[#This Row],[Eficiencia (peso)]]+tblEnlaces[[#This Row],[Exposición (peso)]]+tblEnlaces[[#This Row],[Capacidad (peso)]]+tblEnlaces[[#This Row],[Resiliencia (peso)]] -> 14
E18: I8 | F18: Plataformas digitales | G18: I | H18: 1 | J18: E033 | K18: I6 | L18: G1 | M18: principal | N18: 1 | O18: T | P18: Medio | Q18: Alto | R18: Alto | S18: Alto | T18: Medio | U18: GAFI - FT risks | V18: Banca y tesorería central | W18: =IFERROR(_xlfn.XLOOKUP(tblEnlaces[[#This Row],[Eficiencia]],tblPesosCoste[Valor],#REF!),0)+IFERROR(_xlfn.XLOOKUP(tblEnlaces[[#This Row],[Capacidad]],tblPesosCoste[Valor],#REF!),0)+IFERROR(_xlfn.XLOOKUP(tblEnlaces[[#This Row],[Resiliencia]],tblPesosCoste[Valor],#REF!),0)+IFERROR(_xlfn.XLOOKUP(tblEnlaces[[#This Row],[Coste]],tblPesosCoste[Valor],tblPesosCoste[Coste]),0)+IFERROR(_xlfn.XLOOKUP(tblEnlaces[[#This Row],[Exposición]],tblPesosCoste[Valor],#REF!),0) -> 3 | X18: =IFERROR(_xlfn.XLOOKUP(tblEnlaces[[#This Row],[Coste]],tblPesosCoste[Valor],tblPesosCoste[Coste],0),0) -> 3 | Y18: =IFERROR(_xlfn.XLOOKUP(tblEnlaces[[#This Row],[Eficiencia]],tblPesosValorOperativo[Valor],tblPesosValorOperativo[Eficiencia],0),0) -> 5 | Z18: =IFERROR(_xlfn.XLOOKUP(tblEnlaces[[#This Row],[Exposición]],tblPesosValorOperativo[Valor],tblPesosValorOperativo[Exposición],0),0) -> 1 | AA18: =IFERROR(_xlfn.XLOOKUP(tblEnlaces[[#This Row],[Capacidad]],tblPesosValorOperativo[Valor],tblPesosValorOperativo[Capacidad],0),0) -> 5 | AB18: =IFERROR(_xlfn.XLOOKUP(tblEnlaces[[#This Row],[Resiliencia]],tblPesosValorOperativo[Valor],tblPesosValorOperativo[Resiliencia],0),0) -> 3 | AC18: =tblEnlaces[[#This Row],[Eficiencia (peso)]]+tblEnlaces[[#This Row],[Exposición (peso)]]+tblEnlaces[[#This Row],[Capacidad (peso)]]+tblEnlaces[[#This Row],[Resiliencia (peso)]] -> 14
E19: I9 | F19: Activos virtuales | G19: I | H19: 1 | J19: E034 | K19: I6 | L19: G3 | M19: principal | N19: 1 | O19: E | P19: Medio | Q19: Alto | R19: Alto | S19: Alto | T19: Medio | U19: GAFI - FT risks | V19: Cuentas legítimas/entidades registradas | W19: =IFERROR(_xlfn.XLOOKUP(tblEnlaces[[#This Row],[Eficiencia]],tblPesosCoste[Valor],#REF!),0)+IFERROR(_xlfn.XLOOKUP(tblEnlaces[[#This Row],[Capacidad]],tblPesosCoste[Valor],#REF!),0)+IFERROR(_xlfn.XLOOKUP(tblEnlaces[[#This Row],[Resiliencia]],tblPesosCoste[Valor],#REF!),0)+IFERROR(_xlfn.XLOOKUP(tblEnlaces[[#This Row],[Coste]],tblPesosCoste[Valor],tblPesosCoste[Coste]),0)+IFERROR(_xlfn.XLOOKUP(tblEnlaces[[#This Row],[Exposición]],tblPesosCoste[Valor],#REF!),0) -> 3 | X19: =IFERROR(_xlfn.XLOOKUP(tblEnlaces[[#This Row],[Coste]],tblPesosCoste[Valor],tblPesosCoste[Coste],0),0) -> 3 | Y19: =IFERROR(_xlfn.XLOOKUP(tblEnlaces[[#This Row],[Eficiencia]],tblPesosValorOperativo[Valor],tblPesosValorOperativo[Eficiencia],0),0) -> 5 | Z19: =IFERROR(_xlfn.XLOOKUP(tblEnlaces[[#This Row],[Exposición]],tblPesosValorOperativo[Valor],tblPesosValorOperativo[Exposición],0),0) -> 1 | AA19: =IFERROR(_xlfn.XLOOKUP(tblEnlaces[[#This Row],[Capacidad]],tblPesosValorOperativo[Valor],tblPesosValorOperativo[Capacidad],0),0) -> 5 | AB19: =IFERROR(_xlfn.XLOOKUP(tblEnlaces[[#This Row],[Resiliencia]],tblPesosValorOperativo[Valor],tblPesosValorOperativo[Resiliencia],0),0) -> 3 | AC19: =tblEnlaces[[#This Row],[Eficiencia (peso)]]+tblEnlaces[[#This Row],[Exposición (peso)]]+tblEnlaces[[#This Row],[Capacidad (peso)]]+tblEnlaces[[#This Row],[Resiliencia (peso)]] -> 14
E20: G1 | F20: Tesorería central | G20: G | H20: 1 | J20: E048 | K20: G3 | L20: I6 | M20: principal | N20: 1 | O20: E | P20: Medio | Q20: Alto | R20: Alto | S20: Alto | T20: Medio | U20: GAFI - FT risks | V20: Facilitador → banca | W20: =IFERROR(_xlfn.XLOOKUP(tblEnlaces[[#This Row],[Eficiencia]],tblPesosCoste[Valor],#REF!),0)+IFERROR(_xlfn.XLOOKUP(tblEnlaces[[#This Row],[Capacidad]],tblPesosCoste[Valor],#REF!),0)+IFERROR(_xlfn.XLOOKUP(tblEnlaces[[#This Row],[Resiliencia]],tblPesosCoste[Valor],#REF!),0)+IFERROR(_xlfn.XLOOKUP(tblEnlaces[[#This Row],[Coste]],tblPesosCoste[Valor],tblPesosCoste[Coste]),0)+IFERROR(_xlfn.XLOOKUP(tblEnlaces[[#This Row],[Exposición]],tblPesosCoste[Valor],#REF!),0) -> 3 | X20: =IFERROR(_xlfn.XLOOKUP(tblEnlaces[[#This Row],[Coste]],tblPesosCoste[Valor],tblPesosCoste[Coste],0),0) -> 3 | Y20: =IFERROR(_xlfn.XLOOKUP(tblEnlaces[[#This Row],[Eficiencia]],tblPesosValorOperativo[Valor],tblPesosValorOperativo[Eficiencia],0),0) -> 5 | Z20: =IFERROR(_xlfn.XLOOKUP(tblEnlaces[[#This Row],[Exposición]],tblPesosValorOperativo[Valor],tblPesosValorOperativo[Exposición],0),0) -> 1 | AA20: =IFERROR(_xlfn.XLOOKUP(tblEnlaces[[#This Row],[Capacidad]],tblPesosValorOperativo[Valor],tblPesosValorOperativo[Capacidad],0),0) -> 5 | AB20: =IFERROR(_xlfn.XLOOKUP(tblEnlaces[[#This Row],[Resiliencia]],tblPesosValorOperativo[Valor],tblPesosValorOperativo[Resiliencia],0),0) -> 3 | AC20: =tblEnlaces[[#This Row],[Eficiencia (peso)]]+tblEnlaces[[#This Row],[Exposición (peso)]]+tblEnlaces[[#This Row],[Capacidad (peso)]]+tblEnlaces[[#This Row],[Resiliencia (peso)]] -> 14
... E23: D | F23: Destino operativo | G23: D | H23: 1 | J23: E023 | K23: I1 | L23: I2 | M23: principal | N23: 1 | O23: T | P23: Medio | Q23: Alto | R23: Bajo | S23: Medio | T23: Alto | U23: GAFI - FT risks | V23: Efectivo combinado con hawala | W23: =IFERROR(_xlfn.XLOOKUP(tblEnlaces[[#This Row],[Eficiencia]],tblPesosCoste[Valor],#REF!),0)+IFERROR(_xlfn.XLOOKUP(tblEnlaces[[#This Row],[Capacidad]],tblPesosCoste[Valor],#REF!),0)+IFERROR(_xlfn.XLOOKUP(tblEnlaces[[#This Row],[Resiliencia]],tblPesosCoste[Valor],#REF!),0)+IFERROR(_xlfn.XLOOKUP(tblEnlaces[[#This Row],[Coste]],tblPesosCoste[Valor],tblPesosCoste[Coste]),0)+IFERROR(_xlfn.XLOOKUP(tblEnlaces[[#This Row],[Exposición]],tblPesosCoste[Valor],#REF!),0) -> 3 | X23: =IFERROR(_xlfn.XLOOKUP(tblEnlaces[[#This Row],[Coste]],tblPesosCoste[Valor],tblPesosCoste[Coste],0),0) -> 3 | Y23: =IFERROR(_xlfn.XLOOKUP(tblEnlaces[[#This Row],[Eficiencia]],tblPesosValorOperativo[Valor],tblPesosValorOperativo[Eficiencia],0),0) -> 5 | Z23: =IFERROR(_xlfn.XLOOKUP(tblEnlaces[[#This Row],[Exposición]],tblPesosValorOperativo[Valor],tblPesosValorOperativo[Exposición],0),0) -> 5 | AA23: =IFERROR(_xlfn.XLOOKUP(tblEnlaces[[#This Row],[Capacidad]],tblPesosValorOperativo[Valor],tblPesosValorOperativo[Capacidad],0),0) -> 3 | AB23: =IFERROR(_xlfn.XLOOKUP(tblEnlaces[[#This Row],[Resiliencia]],tblPesosValorOperativo[Valor],tblPesosValorOperativo[Resiliencia],0),0) -> 5 | AC23: =tblEnlaces[[#This Row],[Eficiencia (peso)]]+tblEnlaces[[#This Row],[Exposición (peso)]]+tblEnlaces[[#This Row],[Capacidad (peso)]]+tblEnlaces[[#This Row],[Resiliencia (peso)]] -> 18
J24: E043 | K24: G2 | L24: I2 | M24: principal | N24: 1 | O24: E | P24: Medio | Q24: Alto | R24: Bajo | S24: Medio | T24: Alto | U24: GAFI - FT risks | V24: Centros regionales y hawala | W24: =IFERROR(_xlfn.XLOOKUP(tblEnlaces[[#This Row],[Eficiencia]],tblPesosCoste[Valor],#REF!),0)+IFERROR(_xlfn.XLOOKUP(tblEnlaces[[#This Row],[Capacidad]],tblPesosCoste[Valor],#REF!),0)+IFERROR(_xlfn.XLOOKUP(tblEnlaces[[#This Row],[Resiliencia]],tblPesosCoste[Valor],#REF!),0)+IFERROR(_xlfn.XLOOKUP(tblEnlaces[[#This Row],[Coste]],tblPesosCoste[Valor],tblPesosCoste[Coste]),0)+IFERROR(_xlfn.XLOOKUP(tblEnlaces[[#This Row],[Exposición]],tblPesosCoste[Valor],#REF!),0) -> 3 | X24: =IFERROR(_xlfn.XLOOKUP(tblEnlaces[[#This Row],[Coste]],tblPesosCoste[Valor],tblPesosCoste[Coste],0),0) -> 3 | Y24: =IFERROR(_xlfn.XLOOKUP(tblEnlaces[[#This Row],[Eficiencia]],tblPesosValorOperativo[Valor],tblPesosValorOperativo[Eficiencia],0),0) -> 5 | Z24: =IFERROR(_xlfn.XLOOKUP(tblEnlaces[[#This Row],[Exposición]],tblPesosValorOperativo[Valor],tblPesosValorOperativo[Exposición],0),0) -> 5 | AA24: =IFERROR(_xlfn.XLOOKUP(tblEnlaces[[#This Row],[Capacidad]],tblPesosValorOperativo[Valor],tblPesosValorOperativo[Capacidad],0),0) -> 3 | AB24: =IFERROR(_xlfn.XLOOKUP(tblEnlaces[[#This Row],[Resiliencia]],tblPesosValorOperativo[Valor],tblPesosValorOperativo[Resiliencia],0),0) -> 5 | AC24: =tblEnlaces[[#This Row],[Eficiencia (peso)]]+tblEnlaces[[#This Row],[Exposición (peso)]]+tblEnlaces[[#This Row],[Capacidad (peso)]]+tblEnlaces[[#This Row],[Resiliencia (peso)]] -> 18
J25: E053 | K25: I2 | L25: D | M25: secundario | N25: 1 | O25: E | P25: Medio | Q25: Alto | R25: Bajo | S25: Medio | T25: Medio-Alto | U25: GAFI - FT risks | V25: Hawala directa al receptor final | W25: =IFERROR(_xlfn.XLOOKUP(tblEnlaces[[#This Row],[Eficiencia]],tblPesosCoste[Valor],#REF!),0)+IFERROR(_xlfn.XLOOKUP(tblEnlaces[[#This Row],[Capacidad]],tblPesosCoste[Valor],#REF!),0)+IFERROR(_xlfn.XLOOKUP(tblEnlaces[[#This Row],[Resiliencia]],tblPesosCoste[Valor],#REF!),0)+IFERROR(_xlfn.XLOOKUP(tblEnlaces[[#This Row],[Coste]],tblPesosCoste[Valor],tblPesosCoste[Coste]),0)+IFERROR(_xlfn.XLOOKUP(tblEnlaces[[#This Row],[Exposición]],tblPesosCoste[Valor],#REF!),0) -> 3 | X25: =IFERROR(_xlfn.XLOOKUP(tblEnlaces[[#This Row],[Coste]],tblPesosCoste[Valor],tblPesosCoste[Coste],0),0) -> 3 | Y25: =IFERROR(_xlfn.XLOOKUP(tblEnlaces[[#This Row],[Eficiencia]],tblPesosValorOperativo[Valor],tblPesosValorOperativo[Eficiencia],0),0) -> 5 | Z25: =IFERROR(_xlfn.XLOOKUP(tblEnlaces[[#This Row],[Exposición]],tblPesosValorOperativo[Valor],tblPesosValorOperativo[Exposición],0),0) -> 5 | AA25: =IFERROR(_xlfn.XLOOKUP(tblEnlaces[[#This Row],[Capacidad]],tblPesosValorOperativo[Valor],tblPesosValorOperativo[Capacidad],0),0) -> 3 | AB25: =IFERROR(_xlfn.XLOOKUP(tblEnlaces[[#This Row],[Resiliencia]],tblPesosValorOperativo[Valor],tblPesosValorOperativo[Resiliencia],0),0) -> 4 | AC25: =tblEnlaces[[#This Row],[Eficiencia (peso)]]+tblEnlaces[[#This Row],[Exposición (peso)]]+tblEnlaces[[#This Row],[Capacidad (peso)]]+tblEnlaces[[#This Row],[Resiliencia (peso)]] -> 17
J26: E007 | K26: O2 | L26: I2 | M26: principal | N26: 1 | O26: T | P26: Medio | Q26: Alto | R26: Bajo | S26: Medio-Alto | T26: Alto | U26: GAFI - FT risks | V26: Flujos transfronterizos vía hawala/HOSSP | W26: =IFERROR(_xlfn.XLOOKUP(tblEnlaces[[#This Row],[Eficiencia]],tblPesosCoste[Valor],#REF!),0)+IFERROR(_xlfn.XLOOKUP(tblEnlaces[[#This Row],[Capacidad]],tblPesosCoste[Valor],#REF!),0)+IFERROR(_xlfn.XLOOKUP(tblEnlaces[[#This Row],[Resiliencia]],tblPesosCoste[Valor],#REF!),0)+IFERROR(_xlfn.XLOOKUP(tblEnlaces[[#This Row],[Coste]],tblPesosCoste[Valor],tblPesosCoste[Coste]),0)+IFERROR(_xlfn.XLOOKUP(tblEnlaces[[#This Row],[Exposición]],tblPesosCoste[Valor],#REF!),0) -> 3 | X26: =IFERROR(_xlfn.XLOOKUP(tblEnlaces[[#This Row],[Coste]],tblPesosCoste[Valor],tblPesosCoste[Coste],0),0) -> 3 | Y26: =IFERROR(_xlfn.XLOOKUP(tblEnlaces[[#This Row],[Eficiencia]],tblPesosValorOperativo[Valor],tblPesosValorOperativo[Eficiencia],0),0) -> 5 | Z26: =IFERROR(_xlfn.XLOOKUP(tblEnlaces[[#This Row],[Exposición]],tblPesosValorOperativo[Valor],tblPesosValorOperativo[Exposición],0),0) -> 5 | AA26: =IFERROR(_xlfn.XLOOKUP(tblEnlaces[[#This Row],[Capacidad]],tblPesosValorOperativo[Valor],tblPesosValorOperativo[Capacidad],0),0) -> 4 | AB26: =IFERROR(_xlfn.XLOOKUP(tblEnlaces[[#This Row],[Resiliencia]],tblPesosValorOperativo[Valor],tblPesosValorOperativo[Resiliencia],0),0) -> 5 | AC26: =tblEnlaces[[#This Row],[Eficiencia (peso)]]+tblEnlaces[[#This Row],[Exposición (peso)]]+tblEnlaces[[#This Row],[Capacidad (peso)]]+tblEnlaces[[#This Row],[Resiliencia (peso)]] -> 19
J27: E010 | K27: O3 | L27: I2 | M27: principal | N27: 1 | O27: E | P27: Medio | Q27: Alto | R27: Bajo | S27: Medio-Alto | T27: Alto | U27: GAFI - FT risks | V27: Recursos naturales → hawala en casos | W27: =IFERROR(_xlfn.XLOOKUP(tblEnlaces[[#This Row],[Eficiencia]],tblPesosCoste[Valor],#REF!),0)+IFERROR(_xlfn.XLOOKUP(tblEnlaces[[#This Row],[Capacidad]],tblPesosCoste[Valor],#REF!),0)+IFERROR(_xlfn.XLOOKUP(tblEnlaces[[#This Row],[Resiliencia]],tblPesosCoste[Valor],#REF!),0)+IFERROR(_xlfn.XLOOKUP(tblEnlaces[[#This Row],[Coste]],tblPesosCoste[Valor],tblPesosCoste[Coste]),0)+IFERROR(_xlfn.XLOOKUP(tblEnlaces[[#This Row],[Exposición]],tblPesosCoste[Valor],#REF!),0) -> 3 | X27: =IFERROR(_xlfn.XLOOKUP(tblEnlaces[[#This Row],[Coste]],tblPesosCoste[Valor],tblPesosCoste[Coste],0),0) -> 3 | Y27: =IFERROR(_xlfn.XLOOKUP(tblEnlaces[[#This Row],[Eficiencia]],tblPesosValorOperativo[Valor],tblPesosValorOperativo[Eficiencia],0),0) -> 5 | Z27: =IFERROR(_xlfn.XLOOKUP(tblEnlaces[[#This Row],[Exposición]],tblPesosValorOperativo[Valor],tblPesosValorOperativo[Exposición],0),0) -> 5 | AA27: =IFERROR(_xlfn.XLOOKUP(tblEnlaces[[#This Row],[Capacidad]],tblPesosValorOperativo[Valor],tblPesosValorOperativo[Capacidad],0),0) -> 4 | AB27: =IFERROR(_xlfn.XLOOKUP(tblEnlaces[[#This Row],[Resiliencia]],tblPesosValorOperativo[Valor],tblPesosValorOperativo[Resiliencia],0),0) -> 5 | AC27: =tblEnlaces[[#This Row],[Eficiencia (peso)]]+tblEnlaces[[#This Row],[Exposición (peso)]]+tblEnlaces[[#This Row],[Capacidad (peso)]]+tblEnlaces[[#This Row],[Resiliencia (peso)]] -> 19
B28: FLUJOS POSIBLES | J28: E027 | K28: I2 | L28: G2 | M28: principal | N28: 1 | O28: E | P28: Medio | Q28: Alto | R28: Bajo | S28: Medio-Alto | T28: Alto | U28: GAFI - FT risks | V28: Hawala y centros regionales | W28: =IFERROR(_xlfn.XLOOKUP(tblEnlaces[[#This Row],[Eficiencia]],tblPesosCoste[Valor],#REF!),0)+IFERROR(_xlfn.XLOOKUP(tblEnlaces[[#This Row],[Capacidad]],tblPesosCoste[Valor],#REF!),0)+IFERROR(_xlfn.XLOOKUP(tblEnlaces[[#This Row],[Resiliencia]],tblPesosCoste[Valor],#REF!),0)+IFERROR(_xlfn.XLOOKUP(tblEnlaces[[#This Row],[Coste]],tblPesosCoste[Valor],tblPesosCoste[Coste]),0)+IFERROR(_xlfn.XLOOKUP(tblEnlaces[[#This Row],[Exposición]],tblPesosCoste[Valor],#REF!),0) -> 3 | X28: =IFERROR(_xlfn.XLOOKUP(tblEnlaces[[#This Row],[Coste]],tblPesosCoste[Valor],tblPesosCoste[Coste],0),0) -> 3 | Y28: =IFERROR(_xlfn.XLOOKUP(tblEnlaces[[#This Row],[Eficiencia]],tblPesosValorOperativo[Valor],tblPesosValorOperativo[Eficiencia],0),0) -> 5 | Z28: =IFERROR(_xlfn.XLOOKUP(tblEnlaces[[#This Row],[Exposición]],tblPesosValorOperativo[Valor],tblPesosValorOperativo[Exposición],0),0) -> 5 | AA28: =IFERROR(_xlfn.XLOOKUP(tblEnlaces[[#This Row],[Capacidad]],tblPesosValorOperativo[Valor],tblPesosValorOperativo[Capacidad],0),0) -> 4 | AB28: =IFERROR(_xlfn.XLOOKUP(tblEnlaces[[#This Row],[Resiliencia]],tblPesosValorOperativo[Valor],tblPesosValorOperativo[Resiliencia],0),0) -> 5 | AC28: =tblEnlaces[[#This Row],[Eficiencia (peso)]]+tblEnlaces[[#This Row],[Exposición (peso)]]+tblEnlaces[[#This Row],[Capacidad (peso)]]+tblEnlaces[[#This Row],[Resiliencia (peso)]] -> 19
B29: Origen → Intermediario → Gestión → Intermediario → Destino | J29: E026 | K29: I2 | L29: G1 | M29: secundario | N29: 1 | O29: T | P29: Medio | Q29: Alto | R29: Bajo-Medio | S29: Medio | T29: Medio | U29: GAFI - FT risks | V29: Hawala alimenta gestión central | W29: =IFERROR(_xlfn.XLOOKUP(tblEnlaces[[#This Row],[Eficiencia]],tblPesosCoste[Valor],#REF!),0)+IFERROR(_xlfn.XLOOKUP(tblEnlaces[[#This Row],[Capacidad]],tblPesosCoste[Valor],#REF!),0)+IFERROR(_xlfn.XLOOKUP(tblEnlaces[[#This Row],[Resiliencia]],tblPesosCoste[Valor],#REF!),0)+IFERROR(_xlfn.XLOOKUP(tblEnlaces[[#This Row],[Coste]],tblPesosCoste[Valor],tblPesosCoste[Coste]),0)+IFERROR(_xlfn.XLOOKUP(tblEnlaces[[#This Row],[Exposición]],tblPesosCoste[Valor],#REF!),0) -> 3 | X29: =IFERROR(_xlfn.XLOOKUP(tblEnlaces[[#This Row],[Coste]],tblPesosCoste[Valor],tblPesosCoste[Coste],0),0) -> 3 | Y29: =IFERROR(_xlfn.XLOOKUP(tblEnlaces[[#This Row],[Eficiencia]],tblPesosValorOperativo[Valor],tblPesosValorOperativo[Eficiencia],0),0) -> 5 | Z29: =IFERROR(_xlfn.XLOOKUP(tblEnlaces[[#This Row],[Exposición]],tblPesosValorOperativo[Valor],tblPesosValorOperativo[Exposición],0),0) -> 4 | AA29: =IFERROR(_xlfn.XLOOKUP(tblEnlaces[[#This Row],[Capacidad]],tblPesosValorOperativo[Valor],tblPesosValorOperativo[Capacidad],0),0) -> 3 | AB29: =IFERROR(_xlfn.XLOOKUP(tblEnlaces[[#This Row],[Resiliencia]],tblPesosValorOperativo[Valor],tblPesosValorOperativo[Resiliencia],0),0) -> 3 | AC29: =tblEnlaces[[#This Row],[Eficiencia (peso)]]+tblEnlaces[[#This Row],[Exposición (peso)]]+tblEnlaces[[#This Row],[Capacidad (peso)]]+tblEnlaces[[#This Row],[Resiliencia (peso)]] -> 15
B30: (ej. Extorsión → efectivo → hawala → centro regional → efectivo → combatiente) | J30: E003 | K30: O1 | L30: I3 | M30: principal | N30: 1 | O30: E | P30: Medio | Q30: Alto | R30: Medio | S30: Medio | T30: Medio | U30: GAFI - FT risks | V30: Uso de MVTS/remesas en casos ISIL | W30: =IFERROR(_xlfn.XLOOKUP(tblEnlaces[[#This Row],[Eficiencia]],tblPesosCoste[Valor],#REF!),0)+IFERROR(_xlfn.XLOOKUP(tblEnlaces[[#This Row],[Capacidad]],tblPesosCoste[Valor],#REF!),0)+IFERROR(_xlfn.XLOOKUP(tblEnlaces[[#This Row],[Resiliencia]],tblPesosCoste[Valor],#REF!),0)+IFERROR(_xlfn.XLOOKUP(tblEnlaces[[#This Row],[Coste]],tblPesosCoste[Valor],tblPesosCoste[Coste]),0)+IFERROR(_xlfn.XLOOKUP(tblEnlaces[[#This Row],[Exposición]],tblPesosCoste[Valor],#REF!),0) -> 3 | X30: =IFERROR(_xlfn.XLOOKUP(tblEnlaces[[#This Row],[Coste]],tblPesosCoste[Valor],tblPesosCoste[Coste],0),0) -> 3 | Y30: =IFERROR(_xlfn.XLOOKUP(tblEnlaces[[#This Row],[Eficiencia]],tblPesosValorOperativo[Valor],tblPesosValorOperativo[Eficiencia],0),0) -> 5 | Z30: =IFERROR(_xlfn.XLOOKUP(tblEnlaces[[#This Row],[Exposición]],tblPesosValorOperativo[Valor],tblPesosValorOperativo[Exposición],0),0) -> 3 | AA30: =IFERROR(_xlfn.XLOOKUP(tblEnlaces[[#This Row],[Capacidad]],tblPesosValorOperativo[Valor],tblPesosValorOperativo[Capacidad],0),0) -> 3 | AB30: =IFERROR(_xlfn.XLOOKUP(tblEnlaces[[#This Row],[Resiliencia]],tblPesosValorOperativo[Valor],tblPesosValorOperativo[Resiliencia],0),0) -> 3 | AC30: =tblEnlaces[[#This Row],[Eficiencia (peso)]]+tblEnlaces[[#This Row],[Exposición (peso)]]+tblEnlaces[[#This Row],[Capacidad (peso)]]+tblEnlaces[[#This Row],[Resiliencia (peso)]] -> 14
J31: E008 | K31: O2 | L31: I3 | M31: secundario | N31: 1 | O31: T | P31: Medio | Q31: Alto | R31: Medio | S31: Medio | T31: Medio | U31: GAFI - FT risks | V31: Remesas/MVTS asociadas a beneficios delictivos | W31: =IFERROR(_xlfn.XLOOKUP(tblEnlaces[[#This Row],[Eficiencia]],tblPesosCoste[Valor],#REF!),0)+IFERROR(_xlfn.XLOOKUP(tblEnlaces[[#This Row],[Capacidad]],tblPesosCoste[Valor],#REF!),0)+IFERROR(_xlfn.XLOOKUP(tblEnlaces[[#This Row],[Resiliencia]],tblPesosCoste[Valor],#REF!),0)+IFERROR(_xlfn.XLOOKUP(tblEnlaces[[#This Row],[Coste]],tblPesosCoste[Valor],tblPesosCoste[Coste]),0)+IFERROR(_xlfn.XLOOKUP(tblEnlaces[[#This Row],[Exposición]],tblPesosCoste[Valor],#REF!),0) -> 3 | X31: =IFERROR(_xlfn.XLOOKUP(tblEnlaces[[#This Row],[Coste]],tblPesosCoste[Valor],tblPesosCoste[Coste],0),0) -> 3 | Y31: =IFERROR(_xlfn.XLOOKUP(tblEnlaces[[#This Row],[Eficiencia]],tblPesosValorOperativo[Valor],tblPesosValorOperativo[Eficiencia],0),0) -> 5 | Z31: =IFERROR(_xlfn.XLOOKUP(tblEnlaces[[#This Row],[Exposición]],tblPesosValorOperativo[Valor],tblPesosValorOperativo[Exposición],0),0) -> 3 | AA31: =IFERROR(_xlfn.XLOOKUP(tblEnlaces[[#This Row],[Capacidad]],tblPesosValorOperativo[Valor],tblPesosValorOperativo[Capacidad],0),0) -> 3 | AB31: =IFERROR(_xlfn.XLOOKUP(tblEnlaces[[#This Row],[Resiliencia]],tblPesosValorOperativo[Valor],tblPesosValorOperativo[Resiliencia],0),0) -> 3 | AC31: =tblEnlaces[[#This Row],[Eficiencia (peso)]]+tblEnlaces[[#This Row],[Exposición (peso)]]+tblEnlaces[[#This Row],[Capacidad (peso)]]+tblEnlaces[[#This Row],[Resiliencia (peso)]] -> 14
J32: E019 | K32: O6 | L32: I3 | M32: secundario | N32: 1 | O32: E | P32: Medio | Q32: Alto | R32: Medio | S32: Medio | T32: Medio | U32: GAFI - FT risks | V32: ISIL: MVTS/remesas | W32: =IFERROR(_xlfn.XLOOKUP(tblEnlaces[[#This Row],[Eficiencia]],tblPesosCoste[Valor],#REF!),0)+IFERROR(_xlfn.XLOOKUP(tblEnlaces[[#This Row],[Capacidad]],tblPesosCoste[Valor],#REF!),0)+IFERROR(_xlfn.XLOOKUP(tblEnlaces[[#This Row],[Resiliencia]],tblPesosCoste[Valor],#REF!),0)+IFERROR(_xlfn.XLOOKUP(tblEnlaces[[#This Row],[Coste]],tblPesosCoste[Valor],tblPesosCoste[Coste]),0)+IFERROR(_xlfn.XLOOKUP(tblEnlaces[[#This Row],[Exposición]],tblPesosCoste[Valor],#REF!),0) -> 3 | X32: =IFERROR(_xlfn.XLOOKUP(tblEnlaces[[#This Row],[Coste]],tblPesosCoste[Valor],tblPesosCoste[Coste],0),0) -> 3 | Y32: =IFERROR(_xlfn.XLOOKUP(tblEnlaces[[#This Row],[Eficiencia]],tblPesosValorOperativo[Valor],tblPesosValorOperativo[Eficiencia],0),0) -> 5 | Z32: =IFERROR(_xlfn.XLOOKUP(tblEnlaces[[#This Row],[Exposición]],tblPesosValorOperativo[Valor],tblPesosValorOperativo[Exposición],0),0) -> 3 | AA32: =IFERROR(_xlfn.XLOOKUP(tblEnlaces[[#This Row],[Capacidad]],tblPesosValorOperativo[Valor],tblPesosValorOperativo[Capacidad],0),0) -> 3 | AB32: =IFERROR(_xlfn.XLOOKUP(tblEnlaces[[#This Row],[Resiliencia]],tblPesosValorOperativo[Valor],tblPesosValorOperativo[Resiliencia],0),0) -> 3 | AC32: =tblEnlaces[[#This Row],[Eficiencia (peso)]]+tblEnlaces[[#This Row],[Exposición (peso)]]+tblEnlaces[[#This Row],[Capacidad (peso)]]+tblEnlaces[[#This Row],[Resiliencia (peso)]] -> 14
J33: E029 | K33: I3 | L33: G3 | M33: secundario | N33: 1 | O33: T | P33: Medio | Q33: Alto | R33: Medio | S33: Medio | T33: Medio | U33: GAFI - FT risks | V33: MVTS y facilitadores externos | W33: =IFERROR(_xlfn.XLOOKUP(tblEnlaces[[#This Row],[Eficiencia]],tblPesosCoste[Valor],#REF!),0)+IFERROR(_xlfn.XLOOKUP(tblEnlaces[[#This Row],[Capacidad]],tblPesosCoste[Valor],#REF!),0)+IFERROR(_xlfn.XLOOKUP(tblEnlaces[[#This Row],[Resiliencia]],tblPesosCoste[Valor],#REF!),0)+IFERROR(_xlfn.XLOOKUP(tblEnlaces[[#This Row],[Coste]],tblPesosCoste[Valor],tblPesosCoste[Coste]),0)+IFERROR(_xlfn.XLOOKUP(tblEnlaces[[#This Row],[Exposición]],tblPesosCoste[Valor],#REF!),0) -> 3 | X33: =IFERROR(_xlfn.XLOOKUP(tblEnlaces[[#This Row],[Coste]],tblPesosCoste[Valor],tblPesosCoste[Coste],0),0) -> 3 | Y33: =IFERROR(_xlfn.XLOOKUP(tblEnlaces[[#This Row],[Eficiencia]],tblPesosValorOperativo[Valor],tblPesosValorOperativo[Eficiencia],0),0) -> 5 | Z33: =IFERROR(_xlfn.XLOOKUP(tblEnlaces[[#This Row],[Exposición]],tblPesosValorOperativo[Valor],tblPesosValorOperativo[Exposición],0),0) -> 3 | AA33: =IFERROR(_xlfn.XLOOKUP(tblEnlaces[[#This Row],[Capacidad]],tblPesosValorOperativo[Valor],tblPesosValorOperativo[Capacidad],0),0) -> 3 | AB33: =IFERROR(_xlfn.XLOOKUP(tblEnlaces[[#This Row],[Resiliencia]],tblPesosValorOperativo[Valor],tblPesosValorOperativo[Resiliencia],0),0) -> 3 | AC33: =tblEnlaces[[#This Row],[Eficiencia (peso)]]+tblEnlaces[[#This Row],[Exposición (peso)]]+tblEnlaces[[#This Row],[Capacidad (peso)]]+tblEnlaces[[#This Row],[Resiliencia (peso)]] -> 14
J34: E044 | K34: G2 | L34: I3 | M34: principal | N34: 1 | O34: E | P34: Medio | Q34: Alto | R34: Medio | S34: Medio | T34: Medio | U34: GAFI - FT risks | V34: Centros regionales y MVTS | W34: =IFERROR(_xlfn.XLOOKUP(tblEnlaces[[#This Row],[Eficiencia]],tblPesosCoste[Valor],#REF!),0)+IFERROR(_xlfn.XLOOKUP(tblEnlaces[[#This Row],[Capacidad]],tblPesosCoste[Valor],#REF!),0)+IFERROR(_xlfn.XLOOKUP(tblEnlaces[[#This Row],[Resiliencia]],tblPesosCoste[Valor],#REF!),0)+IFERROR(_xlfn.XLOOKUP(tblEnlaces[[#This Row],[Coste]],tblPesosCoste[Valor],tblPesosCoste[Coste]),0)+IFERROR(_xlfn.XLOOKUP(tblEnlaces[[#This Row],[Exposición]],tblPesosCoste[Valor],#REF!),0) -> 3 | X34: =IFERROR(_xlfn.XLOOKUP(tblEnlaces[[#This Row],[Coste]],tblPesosCoste[Valor],tblPesosCoste[Coste],0),0) -> 3 | Y34: =IFERROR(_xlfn.XLOOKUP(tblEnlaces[[#This Row],[Eficiencia]],tblPesosValorOperativo[Valor],tblPesosValorOperativo[Eficiencia],0),0) -> 5 | Z34: =IFERROR(_xlfn.XLOOKUP(tblEnlaces[[#This Row],[Exposición]],tblPesosValorOperativo[Valor],tblPesosValorOperativo[Exposición],0),0) -> 3 | AA34: =IFERROR(_xlfn.XLOOKUP(tblEnlaces[[#This Row],[Capacidad]],tblPesosValorOperativo[Valor],tblPesosValorOperativo[Capacidad],0),0) -> 3 | AB34: =IFERROR(_xlfn.XLOOKUP(tblEnlaces[[#This Row],[Resiliencia]],tblPesosValorOperativo[Valor],tblPesosValorOperativo[Resiliencia],0),0) -> 3 | AC34: =tblEnlaces[[#This Row],[Eficiencia (peso)]]+tblEnlaces[[#This Row],[Exposición (peso)]]+tblEnlaces[[#This Row],[Capacidad (peso)]]+tblEnlaces[[#This Row],[Resiliencia (peso)]] -> 14
J35: E054 | K35: I3 | L35: D | M35: secundario | N35: 1 | O35: E | P35: Medio | Q35: Alto | R35: Medio | S35: Medio | T35: Medio | U35: GAFI - FT risks | V35: MVTS/remesas directas al receptor | W35: =IFERROR(_xlfn.XLOOKUP(tblEnlaces[[#This Row],[Eficiencia]],tblPesosCoste[Valor],#REF!),0)+IFERROR(_xlfn.XLOOKUP(tblEnlaces[[#This Row],[Capacidad]],tblPesosCoste[Valor],#REF!),0)+IFERROR(_xlfn.XLOOKUP(tblEnlaces[[#This Row],[Resiliencia]],tblPesosCoste[Valor],#REF!),0)+IFERROR(_xlfn.XLOOKUP(tblEnlaces[[#This Row],[Coste]],tblPesosCoste[Valor],tblPesosCoste[Coste]),0)+IFERROR(_xlfn.XLOOKUP(tblEnlaces[[#This Row],[Exposición]],tblPesosCoste[Valor],#REF!),0) -> 3 | X35: =IFERROR(_xlfn.XLOOKUP(tblEnlaces[[#This Row],[Coste]],tblPesosCoste[Valor],tblPesosCoste[Coste],0),0) -> 3 | Y35: =IFERROR(_xlfn.XLOOKUP(tblEnlaces[[#This Row],[Eficiencia]],tblPesosValorOperativo[Valor],tblPesosValorOperativo[Eficiencia],0),0) -> 5 | Z35: =IFERROR(_xlfn.XLOOKUP(tblEnlaces[[#This Row],[Exposición]],tblPesosValorOperativo[Valor],tblPesosValorOperativo[Exposición],0),0) -> 3 | AA35: =IFERROR(_xlfn.XLOOKUP(tblEnlaces[[#This Row],[Capacidad]],tblPesosValorOperativo[Valor],tblPesosValorOperativo[Capacidad],0),0) -> 3 | AB35: =IFERROR(_xlfn.XLOOKUP(tblEnlaces[[#This Row],[Resiliencia]],tblPesosValorOperativo[Valor],tblPesosValorOperativo[Resiliencia],0),0) -> 3 | AC35: =tblEnlaces[[#This Row],[Eficiencia (peso)]]+tblEnlaces[[#This Row],[Exposición (peso)]]+tblEnlaces[[#This Row],[Capacidad (peso)]]+tblEnlaces[[#This Row],[Resiliencia (peso)]] -> 14
J36: E011 | K36: O3 | L36: I3 | M36: principal | N36: 1 | O36: E | P36: Medio | Q36: Alto | R36: Medio | S36: Medio-Alto | T36: Medio | U36: GAFI - FT risks | V36: Recursos naturales → remesas online/MVTS | W36: =IFERROR(_xlfn.XLOOKUP(tblEnlaces[[#This Row],[Eficiencia]],tblPesosCoste[Valor],#REF!),0)+IFERROR(_xlfn.XLOOKUP(tblEnlaces[[#This Row],[Capacidad]],tblPesosCoste[Valor],#REF!),0)+IFERROR(_xlfn.XLOOKUP(tblEnlaces[[#This Row],[Resiliencia]],tblPesosCoste[Valor],#REF!),0)+IFERROR(_xlfn.XLOOKUP(tblEnlaces[[#This Row],[Coste]],tblPesosCoste[Valor],tblPesosCoste[Coste]),0)+IFERROR(_xlfn.XLOOKUP(tblEnlaces[[#This Row],[Exposición]],tblPesosCoste[Valor],#REF!),0) -> 3 | X36: =IFERROR(_xlfn.XLOOKUP(tblEnlaces[[#This Row],[Coste]],tblPesosCoste[Valor],tblPesosCoste[Coste],0),0) -> 3 | Y36: =IFERROR(_xlfn.XLOOKUP(tblEnlaces[[#This Row],[Eficiencia]],tblPesosValorOperativo[Valor],tblPesosValorOperativo[Eficiencia],0),0) -> 5 | Z36: =IFERROR(_xlfn.XLOOKUP(tblEnlaces[[#This Row],[Exposición]],tblPesosValorOperativo[Valor],tblPesosValorOperativo[Exposición],0),0) -> 3 | AA36: =IFERROR(_xlfn.XLOOKUP(tblEnlaces[[#This Row],[Capacidad]],tblPesosValorOperativo[Valor],tblPesosValorOperativo[Capacidad],0),0) -> 4 | AB36: =IFERROR(_xlfn.XLOOKUP(tblEnlaces[[#This Row],[Resiliencia]],tblPesosValorOperativo[Valor],tblPesosValorOperativo[Resiliencia],0),0) -> 3 | AC36: =tblEnlaces[[#This Row],[Eficiencia (peso)]]+tblEnlaces[[#This Row],[Exposición (peso)]]+tblEnlaces[[#This Row],[Capacidad (peso)]]+tblEnlaces[[#This Row],[Resiliencia (peso)]] -> 15
J37: E028 | K37: I3 | L37: G2 | M37: principal | N37: 1 | O37: E | P37: Medio | Q37: Alto | R37: Medio | S37: Medio-Alto | T37: Medio | U37: GAFI - FT risks | V37: MVTS/remesas y facilitadores regionales | W37: =IFERROR(_xlfn.XLOOKUP(tblEnlaces[[#This Row],[Eficiencia]],tblPesosCoste[Valor],#REF!),0)+IFERROR(_xlfn.XLOOKUP(tblEnlaces[[#This Row],[Capacidad]],tblPesosCoste[Valor],#REF!),0)+IFERROR(_xlfn.XLOOKUP(tblEnlaces[[#This Row],[Resiliencia]],tblPesosCoste[Valor],#REF!),0)+IFERROR(_xlfn.XLOOKUP(tblEnlaces[[#This Row],[Coste]],tblPesosCoste[Valor],tblPesosCoste[Coste]),0)+IFERROR(_xlfn.XLOOKUP(tblEnlaces[[#This Row],[Exposición]],tblPesosCoste[Valor],#REF!),0) -> 3 | X37: =IFERROR(_xlfn.XLOOKUP(tblEnlaces[[#This Row],[Coste]],tblPesosCoste[Valor],tblPesosCoste[Coste],0),0) -> 3 | Y37: =IFERROR(_xlfn.XLOOKUP(tblEnlaces[[#This Row],[Eficiencia]],tblPesosValorOperativo[Valor],tblPesosValorOperativo[Eficiencia],0),0) -> 5 | Z37: =IFERROR(_xlfn.XLOOKUP(tblEnlaces[[#This Row],[Exposición]],tblPesosValorOperativo[Valor],tblPesosValorOperativo[Exposición],0),0) -> 3 | AA37: =IFERROR(_xlfn.XLOOKUP(tblEnlaces[[#This Row],[Capacidad]],tblPesosValorOperativo[Valor],tblPesosValorOperativo[Capacidad],0),0) -> 4 | AB37: =IFERROR(_xlfn.XLOOKUP(tblEnlaces[[#This Row],[Resiliencia]],tblPesosValorOperativo[Valor],tblPesosValorOperativo[Resiliencia],0),0) -> 3 | AC37: =tblEnlaces[[#This Row],[Eficiencia (peso)]]+tblEnlaces[[#This Row],[Exposición (peso)]]+tblEnlaces[[#This Row],[Capacidad (peso)]]+tblEnlaces[[#This Row],[Resiliencia (peso)]] -> 15
J38: E032 | K38: I5 | L38: G3 | M38: principal | N38: 1 | O38: T | P38: Medio | Q38: Alto | R38: Medio-Alto | S38: Medio | T38: Medio | U38: GAFI - FT risks | V38: Pagos online y facilitadores | W38: =IFERROR(_xlfn.XLOOKUP(tblEnlaces[[#This Row],[Eficiencia]],tblPesosCoste[Valor],#REF!),0)+IFERROR(_xlfn.XLOOKUP(tblEnlaces[[#This Row],[Capacidad]],tblPesosCoste[Valor],#REF!),0)+IFERROR(_xlfn.XLOOKUP(tblEnlaces[[#This Row],[Resiliencia]],tblPesosCoste[Valor],#REF!),0)+IFERROR(_xlfn.XLOOKUP(tblEnlaces[[#This Row],[Coste]],tblPesosCoste[Valor],tblPesosCoste[Coste]),0)+IFERROR(_xlfn.XLOOKUP(tblEnlaces[[#This Row],[Exposición]],tblPesosCoste[Valor],#REF!),0) -> 3 | X38: =IFERROR(_xlfn.XLOOKUP(tblEnlaces[[#This Row],[Coste]],tblPesosCoste[Valor],tblPesosCoste[Coste],0),0) -> 3 | Y38: =IFERROR(_xlfn.XLOOKUP(tblEnlaces[[#This Row],[Eficiencia]],tblPesosValorOperativo[Valor],tblPesosValorOperativo[Eficiencia],0),0) -> 5 | Z38: =IFERROR(_xlfn.XLOOKUP(tblEnlaces[[#This Row],[Exposición]],tblPesosValorOperativo[Valor],tblPesosValorOperativo[Exposición],0),0) -> 2 | AA38: =IFERROR(_xlfn.XLOOKUP(tblEnlaces[[#This Row],[Capacidad]],tblPesosValorOperativo[Valor],tblPesosValorOperativo[Capacidad],0),0) -> 3 | AB38: =IFERROR(_xlfn.XLOOKUP(tblEnlaces[[#This Row],[Resiliencia]],tblPesosValorOperativo[Valor],tblPesosValorOperativo[Resiliencia],0),0) -> 3 | AC38: =tblEnlaces[[#This Row],[Eficiencia (peso)]]+tblEnlaces[[#This Row],[Exposición (peso)]]+tblEnlaces[[#This Row],[Capacidad (peso)]]+tblEnlaces[[#This Row],[Resiliencia (peso)]] -> 13
J39: E047 | K39: G3 | L39: I5 | M39: principal | N39: 1 | O39: T | P39: Medio | Q39: Alto | R39: Medio-Alto | S39: Medio | T39: Medio | U39: GAFI - FT risks | V39: Facilitador → pagos online | W39: =IFERROR(_xlfn.XLOOKUP(tblEnlaces[[#This Row],[Eficiencia]],tblPesosCoste[Valor],#REF!),0)+IFERROR(_xlfn.XLOOKUP(tblEnlaces[[#This Row],[Capacidad]],tblPesosCoste[Valor],#REF!),0)+IFERROR(_xlfn.XLOOKUP(tblEnlaces[[#This Row],[Resiliencia]],tblPesosCoste[Valor],#REF!),0)+IFERROR(_xlfn.XLOOKUP(tblEnlaces[[#This Row],[Coste]],tblPesosCoste[Valor],tblPesosCoste[Coste]),0)+IFERROR(_xlfn.XLOOKUP(tblEnlaces[[#This Row],[Exposición]],tblPesosCoste[Valor],#REF!),0) -> 3 | X39: =IFERROR(_xlfn.XLOOKUP(tblEnlaces[[#This Row],[Coste]],tblPesosCoste[Valor],tblPesosCoste[Coste],0),0) -> 3 | Y39: =IFERROR(_xlfn.XLOOKUP(tblEnlaces[[#This Row],[Eficiencia]],tblPesosValorOperativo[Valor],tblPesosValorOperativo[Eficiencia],0),0) -> 5 | Z39: =IFERROR(_xlfn.XLOOKUP(tblEnlaces[[#This Row],[Exposición]],tblPesosValorOperativo[Valor],tblPesosValorOperativo[Exposición],0),0) -> 2 | AA39: =IFERROR(_xlfn.XLOOKUP(tblEnlaces[[#This Row],[Capacidad]],tblPesosValorOperativo[Valor],tblPesosValorOperativo[Capacidad],0),0) -> 3 | AB39: =IFERROR(_xlfn.XLOOKUP(tblEnlaces[[#This Row],[Resiliencia]],tblPesosValorOperativo[Valor],tblPesosValorOperativo[Resiliencia],0),0) -> 3 | AC39: =tblEnlaces[[#This Row],[Eficiencia (peso)]]+tblEnlaces[[#This Row],[Exposición (peso)]]+tblEnlaces[[#This Row],[Capacidad (peso)]]+tblEnlaces[[#This Row],[Resiliencia (peso)]] -> 13
J40: E001 | K40: O1 | L40: I1 | M40: principal | N40: 1 | O40: T | P40: Bajo | Q40: Medio | R40: Bajo | S40: Alto | T40: Alto | U40: GAFI - FT risks | V40: Coerción/extorsión y uso intensivo de efectivo | W40: =IFERROR(_xlfn.XLOOKUP(tblEnlaces[[#This Row],[Eficiencia]],tblPesosCoste[Valor],#REF!),0)+IFERROR(_xlfn.XLOOKUP(tblEnlaces[[#This Row],[Capacidad]],tblPesosCoste[Valor],#REF!),0)+IFERROR(_xlfn.XLOOKUP(tblEnlaces[[#This Row],[Resiliencia]],tblPesosCoste[Valor],#REF!),0)+IFERROR(_xlfn.XLOOKUP(tblEnlaces[[#This Row],[Coste]],tblPesosCoste[Valor],tblPesosCoste[Coste]),0)+IFERROR(_xlfn.XLOOKUP(tblEnlaces[[#This Row],[Exposición]],tblPesosCoste[Valor],#REF!),0) -> 5 | X40: =IFERROR(_xlfn.XLOOKUP(tblEnlaces[[#This Row],[Coste]],tblPesosCoste[Valor],tblPesosCoste[Coste],0),0) -> 5 | Y40: =IFERROR(_xlfn.XLOOKUP(tblEnlaces[[#This Row],[Eficiencia]],tblPesosValorOperativo[Valor],tblPesosValorOperativo[Eficiencia],0),0) -> 3 | Z40: =IFERROR(_xlfn.XLOOKUP(tblEnlaces[[#This Row],[Exposición]],tblPesosValorOperativo[Valor],tblPesosValorOperativo[Exposición],0),0) -> 5 | AA40: =IFERROR(_xlfn.XLOOKUP(tblEnlaces[[#This Row],[Capacidad]],tblPesosValorOperativo[Valor],tblPesosValorOperativo[Capacidad],0),0) -> 5 | AB40: =IFERROR(_xlfn.XLOOKUP(tblEnlaces[[#This Row],[Resiliencia]],tblPesosValorOperativo[Valor],tblPesosValorOperativo[Resiliencia],0),0) -> 5 | AC40: =tblEnlaces[[#This Row],[Eficiencia (peso)]]+tblEnlaces[[#This Row],[Exposición (peso)]]+tblEnlaces[[#This Row],[Capacidad (peso)]]+tblEnlaces[[#This Row],[Resiliencia (peso)]] -> 18
J41: E042 | K41: G2 | L41: I1 | M41: principal | N41: 1 | O41: T | P41: Bajo | Q41: Medio | R41: Bajo | S41: Medio | T41: Alto | U41: GAFI - FT risks | V41: Centros regionales y efectivo | W41: =IFERROR(_xlfn.XLOOKUP(tblEnlaces[[#This Row],[Eficiencia]],tblPesosCoste[Valor],#REF!),0)+IFERROR(_xlfn.XLOOKUP(tblEnlaces[[#This Row],[Capacidad]],tblPesosCoste[Valor],#REF!),0)+IFERROR(_xlfn.XLOOKUP(tblEnlaces[[#This Row],[Resiliencia]],tblPesosCoste[Valor],#REF!),0)+IFERROR(_xlfn.XLOOKUP(tblEnlaces[[#This Row],[Coste]],tblPesosCoste[Valor],tblPesosCoste[Coste]),0)+IFERROR(_xlfn.XLOOKUP(tblEnlaces[[#This Row],[Exposición]],tblPesosCoste[Valor],#REF!),0) -> 5 | X41: =IFERROR(_xlfn.XLOOKUP(tblEnlaces[[#This Row],[Coste]],tblPesosCoste[Valor],tblPesosCoste[Coste],0),0) -> 5 | Y41: =IFERROR(_xlfn.XLOOKUP(tblEnlaces[[#This Row],[Eficiencia]],tblPesosValorOperativo[Valor],tblPesosValorOperativo[Eficiencia],0),0) -> 3 | Z41: =IFERROR(_xlfn.XLOOKUP(tblEnlaces[[#This Row],[Exposición]],tblPesosValorOperativo[Valor],tblPesosValorOperativo[Exposición],0),0) -> 5 | AA41: =IFERROR(_xlfn.XLOOKUP(tblEnlaces[[#This Row],[Capacidad]],tblPesosValorOperativo[Valor],tblPesosValorOperativo[Capacidad],0),0) -> 3 | AB41: =IFERROR(_xlfn.XLOOKUP(tblEnlaces[[#This Row],[Resiliencia]],tblPesosValorOperativo[Valor],tblPesosValorOperativo[Resiliencia],0),0) -> 5 | AC41: =tblEnlaces[[#This Row],[Eficiencia (peso)]]+tblEnlaces[[#This Row],[Exposición (peso)]]+tblEnlaces[[#This Row],[Capacidad (peso)]]+tblEnlaces[[#This Row],[Resiliencia (peso)]] -> 16
J42: E052 | K42: I1 | L42: D | M42: secundario | N42: 1 | O42: T | P42: Bajo | Q42: Medio | R42: Bajo | S42: Medio | T42: Medio-Alto | U42: GAFI - FT risks | V42: Ruta directa en redes descentralizadas | W42: =IFERROR(_xlfn.XLOOKUP(tblEnlaces[[#This Row],[Eficiencia]],tblPesosCoste[Valor],#REF!),0)+IFERROR(_xlfn.XLOOKUP(tblEnlaces[[#This Row],[Capacidad]],tblPesosCoste[Valor],#REF!),0)+IFERROR(_xlfn.XLOOKUP(tblEnlaces[[#This Row],[Resiliencia]],tblPesosCoste[Valor],#REF!),0)+IFERROR(_xlfn.XLOOKUP(tblEnlaces[[#This Row],[Coste]],tblPesosCoste[Valor],tblPesosCoste[Coste]),0)+IFERROR(_xlfn.XLOOKUP(tblEnlaces[[#This Row],[Exposición]],tblPesosCoste[Valor],#REF!),0) -> 5 | X42: =IFERROR(_xlfn.XLOOKUP(tblEnlaces[[#This Row],[Coste]],tblPesosCoste[Valor],tblPesosCoste[Coste],0),0) -> 5 | Y42: =IFERROR(_xlfn.XLOOKUP(tblEnlaces[[#This Row],[Eficiencia]],tblPesosValorOperativo[Valor],tblPesosValorOperativo[Eficiencia],0),0) -> 3 | Z42: =IFERROR(_xlfn.XLOOKUP(tblEnlaces[[#This Row],[Exposición]],tblPesosValorOperativo[Valor],tblPesosValorOperativo[Exposición],0),0) -> 5 | AA42: =IFERROR(_xlfn.XLOOKUP(tblEnlaces[[#This Row],[Capacidad]],tblPesosValorOperativo[Valor],tblPesosValorOperativo[Capacidad],0),0) -> 3 | AB42: =IFERROR(_xlfn.XLOOKUP(tblEnlaces[[#This Row],[Resiliencia]],tblPesosValorOperativo[Valor],tblPesosValorOperativo[Resiliencia],0),0) -> 4 | AC42: =tblEnlaces[[#This Row],[Eficiencia (peso)]]+tblEnlaces[[#This Row],[Exposición (peso)]]+tblEnlaces[[#This Row],[Capacidad (peso)]]+tblEnlaces[[#This Row],[Resiliencia (peso)]] -> 15
... J58: E024 | K58: I1 | L58: I4 | M58: secundario | N58: 1 | O58: T | P58: Medio | Q58: Medio-Alto | R58: Medio | S58: Medio | T58: Medio | U58: GAFI - FT risks | V58: Efectivo combinado con dinero móvil | W58: =IFERROR(_xlfn.XLOOKUP(tblEnlaces[[#This Row],[Eficiencia]],tblPesosCoste[Valor],#REF!),0)+IFERROR(_xlfn.XLOOKUP(tblEnlaces[[#This Row],[Capacidad]],tblPesosCoste[Valor],#REF!),0)+IFERROR(_xlfn.XLOOKUP(tblEnlaces[[#This Row],[Resiliencia]],tblPesosCoste[Valor],#REF!),0)+IFERROR(_xlfn.XLOOKUP(tblEnlaces[[#This Row],[Coste]],tblPesosCoste[Valor],tblPesosCoste[Coste]),0)+IFERROR(_xlfn.XLOOKUP(tblEnlaces[[#This Row],[Exposición]],tblPesosCoste[Valor],#REF!),0) -> 3 | X58: =IFERROR(_xlfn.XLOOKUP(tblEnlaces[[#This Row],[Coste]],tblPesosCoste[Valor],tblPesosCoste[Coste],0),0) -> 3 | Y58: =IFERROR(_xlfn.XLOOKUP(tblEnlaces[[#This Row],[Eficiencia]],tblPesosValorOperativo[Valor],tblPesosValorOperativo[Eficiencia],0),0) -> 4 | Z58: =IFERROR(_xlfn.XLOOKUP(tblEnlaces[[#This Row],[Exposición]],tblPesosValorOperativo[Valor],tblPesosValorOperativo[Exposición],0),0) -> 3 | AA58: =IFERROR(_xlfn.XLOOKUP(tblEnlaces[[#This Row],[Capacidad]],tblPesosValorOperativo[Valor],tblPesosValorOperativo[Capacidad],0),0) -> 3 | AB58: =IFERROR(_xlfn.XLOOKUP(tblEnlaces[[#This Row],[Resiliencia]],tblPesosValorOperativo[Valor],tblPesosValorOperativo[Resiliencia],0),0) -> 3 | AC58: =tblEnlaces[[#This Row],[Eficiencia (peso)]]+tblEnlaces[[#This Row],[Exposición (peso)]]+tblEnlaces[[#This Row],[Capacidad (peso)]]+tblEnlaces[[#This Row],[Resiliencia (peso)]] -> 13

Sheet Grafo Visual

Sheet MatrizDeAdyacencia
